<sdf version='1.7'>
  <world name='default'>
    <light name='sun' type='directional'>
      <cast_shadows>1</cast_shadows>
      <pose>0 0 10 0 -0 0</pose>
      <diffuse>0.8 0.8 0.8 1</diffuse>
      <specular>0.2 0.2 0.2 1</specular>
      <attenuation>
        <range>1000</range>
        <constant>0.9</constant>
        <linear>0.01</linear>
        <quadratic>0.001</quadratic>
      </attenuation>
      <direction>-0.5 0.1 -0.9</direction>
      <spot>
        <inner_angle>0</inner_angle>
        <outer_angle>0</outer_angle>
        <falloff>0</falloff>
      </spot>
    </light>
    <model name='ground_plane'>
      <static>1</static>
      <link name='link'>
        <collision name='collision'>
          <geometry>
            <plane>
              <normal>0 0 1</normal>
              <size>100 100</size>
            </plane>
          </geometry>
          <surface>
            <contact>
              <collide_bitmask>65535</collide_bitmask>
              <ode/>
            </contact>
            <friction>
              <ode>
                <mu>100</mu>
                <mu2>50</mu2>
              </ode>
              <torsional>
                <ode/>
              </torsional>
            </friction>
            <bounce/>
          </surface>
          <max_contacts>10</max_contacts>
        </collision>
        <visual name='visual'>
          <cast_shadows>0</cast_shadows>
          <geometry>
            <plane>
              <normal>0 0 1</normal>
              <size>100 100</size>
            </plane>
          </geometry>
          <material>
            <script>
              <uri>file://media/materials/scripts/gazebo.material</uri>
              <name>Gazebo/Grey</name>
            </script>
          </material>
        </visual>
        <self_collide>0</self_collide>
        <enable_wind>0</enable_wind>
        <kinematic>0</kinematic>
      </link>
    </model>
    <gravity>0 0 -9.8</gravity>
    <magnetic_field>6e-06 2.3e-05 -4.2e-05</magnetic_field>
    <atmosphere type='adiabatic'/>
    <physics type='ode'>
      <max_step_size>0.001</max_step_size>
      <real_time_factor>1</real_time_factor>
      <real_time_update_rate>1000</real_time_update_rate>
    </physics>
    <scene>
      <ambient>0.4 0.4 0.4 1</ambient>
      <background>0.7 0.7 0.7 1</background>
      <shadows>1</shadows>
    </scene>
    <wind/>
    <spherical_coordinates>
      <surface_model>EARTH_WGS84</surface_model>
      <latitude_deg>0</latitude_deg>
      <longitude_deg>0</longitude_deg>
      <elevation>0</elevation>
      <heading_deg>0</heading_deg>
    </spherical_coordinates>
    <model name='bd1'>
      <link name='base_link'>
        <inertial>
          <pose>-0.015 0 0.005 0 -0 0</pose>
          <mass>0.5</mass>
          <inertia>
            <ixx>0.000976</ixx>
            <ixy>0</ixy>
            <ixz>0</ixz>
            <iyy>0.001696</iyy>
            <iyz>0</iyz>
            <izz>0.001872</izz>
          </inertia>
        </inertial>
        <collision name='base_link_fixed_joint_lump__body_link_collision_collision'>
          <pose>-0.015 0 0.005 0 -0 0</pose>
          <geometry>
            <box>
              <size>0.18 0.12 0.1</size>
            </box>
          </geometry>
          <surface>
            <contact>
              <ode/>
            </contact>
            <friction>
              <ode/>
              <torsional>
                <ode/>
              </torsional>
            </friction>
            <bounce/>
          </surface>
          <max_contacts>10</max_contacts>
        </collision>
        <visual name='base_link_fixed_joint_lump__body_link_visual'>
          <pose>0 0 0 0 -0 0</pose>
          <geometry>
            <mesh>
              <scale>1 1 1</scale>
              <uri>file:///home/trax/personal-projects/bd1-2/src/bd1_description/mesh/body_m.dae</uri>
            </mesh>
          </geometry>
        </visual>
        <self_collide>0</self_collide>
        <enable_wind>0</enable_wind>
        <kinematic>0</kinematic>
        <contact>
          <collision>body_link_collision__collision</collision>
        </contact>
        <plugin filename='libcontact.so' name='body_link_gazebo_ros_bumper_controller'>
          <alwaysOn>1</alwaysOn>
          <updateRate>100</updateRate>
          <bumperTopicName>body_link_bumper</bumperTopicName>
          <frameName>world</frameName>
          <robotNamespace>/</robotNamespace>
        </plugin>
      </link>
      <joint name='neck_j' type='revolute'>
        <pose relative_to='base_link'>0.03 0 0.04 0 -1.5 0</pose>
        <parent>base_link</parent>
        <child>neck_link</child>
        <axis>
          <xyz>0 1 0</xyz>
          <limit>
            <lower>0</lower>
            <upper>3.14159</upper>
            <effort>30</effort>
            <velocity>2</velocity>
          </limit>
          <dynamics>
            <damping>0.3</damping>
            <friction>0</friction>
            <spring_reference>0</spring_reference>
            <spring_stiffness>0</spring_stiffness>
          </dynamics>
        </axis>
      </joint>
      <link name='neck_link'>
        <pose relative_to='neck_j'>0 0 0 0 -0 0</pose>
        <inertial>
          <pose>0 0 0.035 0 -0 0</pose>
          <mass>0.1</mass>
          <inertia>
            <ixx>0.000872</ixx>
            <ixy>0</ixy>
            <ixz>0</ixz>
            <iyy>0.000832</iyy>
            <iyz>0</iyz>
            <izz>0.000104</izz>
          </inertia>
        </inertial>
        <visual name='neck_link_visual'>
          <pose>0 0 0 0 -0 0</pose>
          <geometry>
            <mesh>
              <scale>1 1 1</scale>
              <uri>file:///home/trax/personal-projects/bd1-2/src/bd1_description/mesh/neck_m.dae</uri>
            </mesh>
          </geometry>
        </visual>
        <self_collide>0</self_collide>
        <enable_wind>0</enable_wind>
        <kinematic>0</kinematic>
      </link>
      <joint name='head_j' type='revolute'>
        <pose relative_to='neck_link'>0 0 0.07 0 1.5 0</pose>
        <parent>neck_link</parent>
        <child>head_link</child>
        <axis>
          <xyz>0 1 0</xyz>
          <limit>
            <lower>-3.14159</lower>
            <upper>3.14159</upper>
            <effort>30</effort>
            <velocity>2</velocity>
          </limit>
          <dynamics>
            <damping>0.3</damping>
            <friction>0</friction>
            <spring_reference>0</spring_reference>
            <spring_stiffness>0</spring_stiffness>
          </dynamics>
        </axis>
      </joint>
      <link name='head_link'>
        <pose relative_to='head_j'>0 0 0 0 -0 0</pose>
        <inertial>
          <pose>0.04 0 0.07 0 -0 0</pose>
          <mass>0.5</mass>
          <inertia>
            <ixx>0.00256</ixx>
            <ixy>0</ixy>
            <ixz>0</ixz>
            <iyy>0.00362</iyy>
            <iyz>0</iyz>
            <izz>0.005668</izz>
          </inertia>
        </inertial>
        <collision name='head_link_collision'>
          <pose>0.04 0 0.07 0 -0 0</pose>
          <geometry>
            <box>
              <size>0.29 0.24 0.08</size>
            </box>
          </geometry>
          <max_contacts>10</max_contacts>
          <surface>
            <contact>
              <ode/>
            </contact>
            <bounce/>
            <friction>
              <torsional>
                <ode/>
              </torsional>
              <ode/>
            </friction>
          </surface>
        </collision>
        <visual name='head_link_visual'>
          <pose>0 0 0 0 -0 0</pose>
          <geometry>
            <mesh>
              <scale>1 1 1</scale>
              <uri>file:///home/trax/personal-projects/bd1-2/src/bd1_description/mesh/head_m.dae</uri>
            </mesh>
          </geometry>
        </visual>
        <self_collide>0</self_collide>
        <enable_wind>0</enable_wind>
        <kinematic>0</kinematic>
      </link>
      <joint name='up_leg_l_j' type='revolute'>
        <pose relative_to='base_link'>0 0.06 0 3.14159 0.070796 3.14159</pose>
        <parent>base_link</parent>
        <child>up_leg_l_link</child>
        <axis>
          <xyz>0 1 0</xyz>
          <limit>
            <lower>-3.14159</lower>
            <upper>0</upper>
            <effort>30</effort>
            <velocity>2</velocity>
          </limit>
          <dynamics>
            <spring_reference>0</spring_reference>
            <spring_stiffness>0</spring_stiffness>
          </dynamics>
        </axis>
      </joint>
      <link name='up_leg_l_link'>
        <pose relative_to='up_leg_l_j'>0 0 0 0 -0 0</pose>
        <inertial>
          <pose>0.065 0.03 0 0 -0 0</pose>
          <mass>0.25</mass>
          <inertia>
            <ixx>0.00032</ixx>
            <ixy>0</ixy>
            <ixz>0</ixz>
            <iyy>0.00144</iyy>
            <iyz>0</iyz>
            <izz>0.001184</izz>
          </inertia>
        </inertial>
        <collision name='up_leg_l_link_collision'>
          <pose>0.065 0.03 0 0 -0 0</pose>
          <geometry>
            <box>
              <size>0.24 0.04 0.12</size>
            </box>
          </geometry>
          <max_contacts>10</max_contacts>
          <surface>
            <contact>
              <ode/>
            </contact>
            <bounce/>
            <friction>
              <torsional>
                <ode/>
              </torsional>
              <ode/>
            </friction>
          </surface>
        </collision>
        <visual name='up_leg_l_link_visual'>
          <pose>0 0 0 0 -0 0</pose>
          <geometry>
            <mesh>
              <scale>1 1 1</scale>
              <uri>file:///home/trax/personal-projects/bd1-2/src/bd1_description/mesh/up_leg_l_m.dae</uri>
            </mesh>
          </geometry>
        </visual>
        <self_collide>0</self_collide>
        <enable_wind>0</enable_wind>
        <kinematic>0</kinematic>
      </link>
      <joint name='mid_leg_l_j' type='revolute'>
        <pose relative_to='up_leg_l_link'>0.15 0.009 0 3.14159 -0.141593 3.14159</pose>
        <parent>up_leg_l_link</parent>
        <child>mid_leg_l_link</child>
        <axis>
          <xyz>0 1 0</xyz>
          <limit>
            <lower>0</lower>
            <upper>3.14159</upper>
            <effort>30</effort>
            <velocity>2</velocity>
          </limit>
          <dynamics>
            <spring_reference>0</spring_reference>
            <spring_stiffness>0</spring_stiffness>
          </dynamics>
        </axis>
      </joint>
      <link name='mid_leg_l_link'>
        <pose relative_to='mid_leg_l_j'>0 0 0 0 -0 0</pose>
        <inertial>
          <pose>0.07 -0.01 0 0 -0 0</pose>
          <mass>0.25</mass>
          <inertia>
            <ixx>8e-05</ixx>
            <ixy>0</ixy>
            <ixz>0</ixz>
            <iyy>0.00104</iyy>
            <iyz>0</iyz>
            <izz>0.000976</izz>
          </inertia>
        </inertial>
        <collision name='mid_leg_l_link_collision'>
          <pose>0.07 -0.01 0 0 -0 0</pose>
          <geometry>
            <box>
              <size>0.22 0.02 0.06</size>
            </box>
          </geometry>
          <max_contacts>10</max_contacts>
          <surface>
            <contact>
              <ode/>
            </contact>
            <bounce/>
            <friction>
              <torsional>
                <ode/>
              </torsional>
              <ode/>
            </friction>
          </surface>
        </collision>
        <visual name='mid_leg_l_link_visual'>
          <pose>0 0 0 0 -0 0</pose>
          <geometry>
            <mesh>
              <scale>1 1 1</scale>
              <uri>file:///home/trax/personal-projects/bd1-2/src/bd1_description/mesh/mid_leg_l_m.dae</uri>
            </mesh>
          </geometry>
        </visual>
        <self_collide>0</self_collide>
        <enable_wind>0</enable_wind>
        <kinematic>0</kinematic>
      </link>
      <joint name='feet_l_j' type='revolute'>
        <pose relative_to='mid_leg_l_link'>0.15 -0.0045 0 0 -0 0</pose>
        <parent>mid_leg_l_link</parent>
        <child>feet_l_link</child>
        <axis>
          <xyz>0 1 0</xyz>
          <limit>
            <lower>-3.14159</lower>
            <upper>0</upper>
            <effort>30</effort>
            <velocity>2</velocity>
          </limit>
          <dynamics>
            <spring_reference>0</spring_reference>
            <spring_stiffness>0</spring_stiffness>
          </dynamics>
        </axis>
      </joint>
      <link name='feet_l_link'>
        <pose relative_to='feet_l_j'>0 0 0 0 -0 0</pose>
        <inertial>
          <pose>0.02 0 -0.065 0 -0 0</pose>
          <mass>0.25</mass>
          <inertia>
            <ixx>8.45e-05</ixx>
            <ixy>0</ixy>
            <ixz>0</ixz>
            <iyy>0.0012625</iyy>
            <iyz>0</iyz>
            <izz>0.001322</izz>
          </inertia>
        </inertial>
        <collision name='feet_l_link_collision'>
          <pose>0.02 0 -0.065 0 -0 0</pose>
          <geometry>
            <box>
              <size>0.25 0.06 0.025</size>
            </box>
          </geometry>
          <surface>
            <contact>
              <ode>
                <kp>20000</kp>
                <kd>1</kd>
              </ode>
            </contact>
            <friction>
              <ode>
                <mu>2</mu>
                <mu2>5</mu2>
              </ode>
              <torsional>
                <ode/>
              </torsional>
            </friction>
            <bounce/>
          </surface>
          <max_contacts>10</max_contacts>
        </collision>
        <visual name='feet_l_link_visual'>
          <pose>0 0 0 0 -0 0</pose>
          <geometry>
            <mesh>
              <scale>1 1 1</scale>
              <uri>file:///home/trax/personal-projects/bd1-2/src/bd1_description/mesh/feet_m.dae</uri>
            </mesh>
          </geometry>
        </visual>
        <self_collide>0</self_collide>
        <enable_wind>0</enable_wind>
        <kinematic>0</kinematic>
      </link>
      <joint name='up_leg_r_j' type='revolute'>
        <pose relative_to='base_link'>0 -0.06 0 3.14159 0.070796 3.14159</pose>
        <parent>base_link</parent>
        <child>up_leg_r_link</child>
        <axis>
          <xyz>0 1 0</xyz>
          <limit>
            <lower>-3.14159</lower>
            <upper>0</upper>
            <effort>30</effort>
            <velocity>2</velocity>
          </limit>
          <dynamics>
            <spring_reference>0</spring_reference>
            <spring_stiffness>0</spring_stiffness>
          </dynamics>
        </axis>
      </joint>
      <link name='up_leg_r_link'>
        <pose relative_to='up_leg_r_j'>0 0 0 0 -0 0</pose>
        <inertial>
          <pose>0.065 -0.03 0 0 -0 0</pose>
          <mass>0.25</mass>
          <inertia>
            <ixx>0.00032</ixx>
            <ixy>0</ixy>
            <ixz>0</ixz>
            <iyy>0.00144</iyy>
            <iyz>0</iyz>
            <izz>0.001184</izz>
          </inertia>
        </inertial>
        <collision name='up_leg_r_link_collision'>
          <pose>0.065 -0.03 0 0 -0 0</pose>
          <geometry>
            <box>
              <size>0.24 0.04 0.12</size>
            </box>
          </geometry>
          <max_contacts>10</max_contacts>
          <surface>
            <contact>
              <ode/>
            </contact>
            <bounce/>
            <friction>
              <torsional>
                <ode/>
              </torsional>
              <ode/>
            </friction>
          </surface>
        </collision>
        <visual name='up_leg_r_link_visual'>
          <pose>0 0 0 0 -0 0</pose>
          <geometry>
            <mesh>
              <scale>1 1 1</scale>
              <uri>file:///home/trax/personal-projects/bd1-2/src/bd1_description/mesh/up_leg_r_m.dae</uri>
            </mesh>
          </geometry>
        </visual>
        <self_collide>0</self_collide>
        <enable_wind>0</enable_wind>
        <kinematic>0</kinematic>
      </link>
      <joint name='mid_leg_r_j' type='revolute'>
        <pose relative_to='up_leg_r_link'>0.15 -0.009 0 3.14159 -0.141593 3.14159</pose>
        <parent>up_leg_r_link</parent>
        <child>mid_leg_r_link</child>
        <axis>
          <xyz>0 1 0</xyz>
          <limit>
            <lower>0</lower>
            <upper>3.14159</upper>
            <effort>30</effort>
            <velocity>2</velocity>
          </limit>
          <dynamics>
            <spring_reference>0</spring_reference>
            <spring_stiffness>0</spring_stiffness>
          </dynamics>
        </axis>
      </joint>
      <link name='mid_leg_r_link'>
        <pose relative_to='mid_leg_r_j'>0 0 0 0 -0 0</pose>
        <inertial>
          <pose>0.07 0.01 0 0 -0 0</pose>
          <mass>0.25</mass>
          <inertia>
            <ixx>8e-05</ixx>
            <ixy>0</ixy>
            <ixz>0</ixz>
            <iyy>0.00104</iyy>
            <iyz>0</iyz>
            <izz>0.000976</izz>
          </inertia>
        </inertial>
        <collision name='mid_leg_r_link_collision'>
          <pose>0.07 0.01 0 0 -0 0</pose>
          <geometry>
            <box>
              <size>0.22 0.02 0.06</size>
            </box>
          </geometry>
          <max_contacts>10</max_contacts>
          <surface>
            <contact>
              <ode/>
            </contact>
            <bounce/>
            <friction>
              <torsional>
                <ode/>
              </torsional>
              <ode/>
            </friction>
          </surface>
        </collision>
        <visual name='mid_leg_r_link_visual'>
          <pose>0 0 0 0 -0 0</pose>
          <geometry>
            <mesh>
              <scale>1 1 1</scale>
              <uri>file:///home/trax/personal-projects/bd1-2/src/bd1_description/mesh/mid_leg_r_m.dae</uri>
            </mesh>
          </geometry>
        </visual>
        <self_collide>0</self_collide>
        <enable_wind>0</enable_wind>
        <kinematic>0</kinematic>
      </link>
      <joint name='feet_r_j' type='revolute'>
        <pose relative_to='mid_leg_r_link'>0.15 0.0045 0 0 -0 0</pose>
        <parent>mid_leg_r_link</parent>
        <child>feet_r_link</child>
        <axis>
          <xyz>0 1 0</xyz>
          <limit>
            <lower>-3.14159</lower>
            <upper>0</upper>
            <effort>30</effort>
            <velocity>2</velocity>
          </limit>
          <dynamics>
            <spring_reference>0</spring_reference>
            <spring_stiffness>0</spring_stiffness>
          </dynamics>
        </axis>
      </joint>
      <link name='feet_r_link'>
        <pose relative_to='feet_r_j'>0 0 0 0 -0 0</pose>
        <inertial>
          <pose>0.02 0 -0.065 0 -0 0</pose>
          <mass>0.25</mass>
          <inertia>
            <ixx>8.45e-05</ixx>
            <ixy>0</ixy>
            <ixz>0</ixz>
            <iyy>0.0012625</iyy>
            <iyz>0</iyz>
            <izz>0.001322</izz>
          </inertia>
        </inertial>
        <collision name='feet_r_link_collision'>
          <pose>0.02 0 -0.065 0 -0 0</pose>
          <geometry>
            <box>
              <size>0.25 0.06 0.025</size>
            </box>
          </geometry>
          <surface>
            <contact>
              <ode>
                <kp>20000</kp>
                <kd>1</kd>
              </ode>
            </contact>
            <friction>
              <ode>
                <mu>2</mu>
                <mu2>5</mu2>
              </ode>
              <torsional>
                <ode/>
              </torsional>
            </friction>
            <bounce/>
          </surface>
          <max_contacts>10</max_contacts>
        </collision>
        <visual name='feet_r_link_visual'>
          <pose>0 0 0 0 -0 0</pose>
          <geometry>
            <mesh>
              <scale>1 1 1</scale>
              <uri>file:///home/trax/personal-projects/bd1-2/src/bd1_description/mesh/feet_m.dae</uri>
            </mesh>
          </geometry>
        </visual>
        <self_collide>0</self_collide>
        <enable_wind>0</enable_wind>
        <kinematic>0</kinematic>
      </link>
      <static>0</static>
      <plugin name='gazebo_ros_control' filename='libgazebo_ros_control.so'>
        <robotSimType>gazebo_ros_control/DefaultRobotHWSim</robotSimType>
        <legacyModeNS>1</legacyModeNS>
        <robotNamespace>/</robotNamespace>
      </plugin>
      <pose>0 0 0.2 0 -0 0</pose>
    </model>
    <model name='Floor'>
      <link name='main'>
        <pose>0 0 0.01 0 -0 0</pose>
        <collision name='main_Collision'>
          <geometry>
            <box>
              <size>40 40 0.01</size>
            </box>
          </geometry>
          <max_contacts>10</max_contacts>
          <surface>
            <contact>
              <ode/>
            </contact>
            <bounce/>
            <friction>
              <torsional>
                <ode/>
              </torsional>
              <ode/>
            </friction>
          </surface>
        </collision>
        <visual name='main_Visual'>
          <geometry>
            <box>
              <size>40 40 0.01</size>
            </box>
          </geometry>
          <material>
            <script>
              <uri>model://Floor/materials/scripts</uri>
              <uri>model://Floor/materials/textures</uri>
              <name>floor</name>
            </script>
          </material>
        </visual>
        <self_collide>0</self_collide>
        <enable_wind>0</enable_wind>
        <kinematic>0</kinematic>
      </link>
      <static>1</static>
      <pose>-1.84718 0.650615 0 0 -0 0</pose>
    </model>
    <state world_name='default'>
      <sim_time>32 927000000</sim_time>
      <real_time>33 463206710</real_time>
      <wall_time>1667524439 570079596</wall_time>
      <iterations>32927</iterations>
      <model name='Floor'>
        <pose>-1.84718 0.650615 0 0 -0 0</pose>
        <scale>1 1 1</scale>
        <link name='main'>
          <pose>-1.84718 0.650615 0.01 0 -0 0</pose>
          <velocity>0 0 0 0 -0 0</velocity>
          <acceleration>0 0 0 0 -0 0</acceleration>
          <wrench>0 0 0 0 -0 0</wrench>
        </link>
      </model>
      <model name='bd1'>
        <pose>-0.150342 0.000288 0.112536 0.002235 -0.076279 0.011948</pose>
        <scale>1 1 1</scale>
        <link name='base_link'>
          <pose>-0.150342 0.000288 0.112536 0.002235 -0.076279 0.011948</pose>
          <velocity>-0.099521 -0.014923 0.061323 -0.076161 0.767065 0.014697</velocity>
          <acceleration>-94.5552 0.190826 291.351 -1.80811 -1.32087 0.031594</acceleration>
          <wrench>-47.2776 0.095413 145.675 0 -0 0</wrench>
        </link>
        <link name='feet_l_link'>
          <pose>-0.149439 0.064983 0.090875 0.004616 -0.010696 0.011716</pose>
          <velocity>-0.077083 -0.038615 -0.183553 -0.511856 -0.962827 0.078297</velocity>
          <acceleration>91.5482 -0.19742 -232.401 0.468914 -1.44682 2.78179</acceleration>
          <wrench>22.8871 -0.049355 -58.1001 0 -0 0</wrench>
        </link>
        <link name='feet_r_link'>
          <pose>-0.147889 -0.064241 0.090924 0.000128 -0.008099 0.012744</pose>
          <velocity>-0.071182 -0.001928 -0.226742 0.28812 -0.981811 -0.137965</velocity>
          <acceleration>96.919 -24.5844 -274.293 1.40967 1.26359 2.16595</acceleration>
          <wrench>24.2298 -6.1461 -68.5734 0 -0 0</wrench>
        </link>
        <link name='head_link'>
          <pose>-0.193473 -0.000328 0.1545 0.002184 -0.073579 0.011952</pose>
          <velocity>-0.066941 -0.01201 -0.045551 -0.061982 0.766787 0.014757</velocity>
          <acceleration>104.55 7.39656 13.4428 -2.66315 -0.882915 3.01711</acceleration>
          <wrench>52.2751 3.69828 6.7214 0 -0 0</wrench>
        </link>
        <link name='mid_leg_l_link'>
          <pose>-0.299487 0.067569 0.090258 0.00466 -0.004368 0.012033</pose>
          <velocity>-0.074919 -0.02367 -0.111431 -0.525455 0.516541 0.03056</velocity>
          <acceleration>-46.7774 3.997 -174.631 -0.162194 0.048408 1.71846</acceleration>
          <wrench>-11.6944 0.99925 -43.6577 0 -0 0</wrench>
        </link>
        <link name='mid_leg_r_link'>
          <pose>-0.297821 -0.070495 0.09004 0.002117 -0.005824 0.012263</pose>
          <velocity>-0.073097 -0.011273 -0.103302 -0.047548 0.821792 -0.023047</velocity>
          <acceleration>-48.843 -1.09718 -191.961 2.79766 1.3477 -0.929557</acceleration>
          <wrench>-12.2108 -0.274294 -47.9903 0 -0 0</wrench>
        </link>
        <link name='neck_link'>
          <pose>-0.123478 0.000519 0.154705 2.50982 -1.56715 -2.49771</pose>
          <velocity>-0.067077 -0.011185 0.040635 -0.030709 -1.23344 0.010289</velocity>
          <acceleration>-34.7882 2.62658 152.871 2.58789 -1.36049 0.692907</acceleration>
          <wrench>-3.47882 0.262659 15.2871 0 -0 0</wrench>
        </link>
        <link name='up_leg_l_link'>
          <pose>-0.151077 0.060299 0.112654 3.13874 0.150137 -3.12983</pose>
          <velocity>-0.099509 -0.017989 0.060477 -0.164886 -1.12818 -0.004382</velocity>
          <acceleration>-74.7844 3.1334 113.256 -0.513775 1.10724 -0.85022</acceleration>
          <wrench>-18.6961 0.78335 28.3141 0 -0 0</wrench>
        </link>
        <link name='up_leg_r_link'>
          <pose>-0.149611 -0.05973 0.112421 3.13951 0.149518 -3.12975</pose>
          <velocity>-0.099511 -0.010209 0.061617 -0.015171 -1.13506 0.004067</velocity>
          <acceleration>-81.857 3.49738 119.963 1.8777 1.35891 1.87583</acceleration>
          <wrench>-20.4642 0.874345 29.9908 0 -0 0</wrench>
        </link>
      </model>
      <model name='ground_plane'>
        <pose>0 0 0 0 -0 0</pose>
        <scale>1 1 1</scale>
        <link name='link'>
          <pose>0 0 0 0 -0 0</pose>
          <velocity>0 0 0 0 -0 0</velocity>
          <acceleration>0 0 0 0 -0 0</acceleration>
          <wrench>0 0 0 0 -0 0</wrench>
        </link>
      </model>
      <light name='sun'>
        <pose>0 0 10 0 -0 0</pose>
      </light>
    </state>
    <gui fullscreen='0'>
      <camera name='user_camera'>
        <pose>5 -5 2 0 0.275643 2.35619</pose>
        <view_controller>orbit</view_controller>
        <projection_type>perspective</projection_type>
      </camera>
    </gui>
  </world>
</sdf>
